Workbook
Name Slicer_Designation: #REF!
Name Slicer_Designation1: #REF!
Name Slicer_Department: #REF!
Name Slicer_TDS_Rate: #REF!
Name Slicer_Department1: #REF!
Name Slicer_Employee_ID: #REF!
Name Slicer_Pay_Month: #REF!

Sheet Raw_Data
A2: Employee ID | B2: Department | C2: Designation | D2: Basic Pay | E2: Allowances | F2: Overtime Amount | G2: Deductions | H2: Gross Salary | I2: Net Salary | J2: Pay Month | K2: Experience | L2: Destination
A3: EMP0001 | B3: Sales | C3: Associate | D3: 18180.08 | E3: 5454.02 | F3: 1000.01 | G3: 1217.4 | H3: 24634.11 | I3: 23416.71 | J3: 45992 | K3: 14 | L3: Delhi-North
A4: EMP0002 | B4: HR | C4: Sr. Manager | D4: 84257.36 | E4: 25277.21 | F4: 9190.23 | G4: 14926 | H4: 118724.8 | I4: 103798.8 | J4: 45658 | K4: 2 | L4: Bangalore-South
A5: EMP0003 | B5: HR | C5: Associate | D5: 19574.19 | E5: 5872.26 | F5: 1978.38 | G5: 155.83 | H5: 27424.83 | I5: 27269 | J5: 45748 | K5: 4 | L5: Chennai-South
A6: EMP0004 | B6: Sales | C6: Sr. Manager | D6: 83234.45 | E6: 24970.33 | F6: 6983.7 | G6: 11216.9 | H6: 115188.48 | I6: 103971.58 | J6: 45778 | K6: 17 | L6: Kolkata-East
A7: EMP0005 | B7: Customer Support | C7: Director | D7: 90233.96 | E7: 27070.19 | F7: 14542.45 | G7: 18898.76 | H7: 131846.6 | I7: 112947.84 | J7: 45809 | K7: 23 | L7: Pune-West
A8: EMP0006 | B8: IT | C8: Executive | D8: 23894.76 | E8: 7168.43 | F8: 3648.7 | G8: 732.69 | H8: 34711.89 | I8: 33979.2 | J8: 45839 | K8: 2 | L8: Hyderabad-South
A9: EMP0007 | B9: HR | C9: Analyst | D9: 33474.94 | E9: 10042.48 | F9: 4041.94 | G9: 8105.57 | H9: 47559.36 | I9: 39453.79 | J9: 45992 | K9: 25 | L9: Chandigarh-North
A10: EMP0008 | B10: Marketing | C10: Manager | D10: 47246.87 | E10: 14174.06 | F10: 8715.11 | G10: 1116.92 | H10: 46129.95 | I10: 51129.95 | J10: 45778 | K10: 18 | L10: Ahmedabad-West
A11: EMP0009 | B11: Customer Support | C11: Sr. Manager | D11: 81081.51 | E11: 24324.45 | F11: 13973.7 | G11: 14043.78 | H11: 119379.66 | I11: 105335.88 | J11: 45992 | K11: 4 | L11: Jaipur-North
A12: EMP0010 | B12: HR | C12: Associate | D12: 22761.1 | E12: 6828.33 | F12: 3519.18 | G12: 6727.42 | H12: 33108.61 | I12: 26381.19 | J12: 45748 | K12: 18 | L12: Mumbai-HO
A13: EMP0011 | B13: Customer Support | C13: Associate | D13: 20736.91 | E13: 6221.07 | F13: 1880.47 | G13: 5189.06 | H13: 28838.45 | I13: 23649.39 | J13: 45717 | K13: 18 | L13: Delhi-North
A14: EMP0012 | B14: IT | C14: Analyst | D14: 27095.07 | E14: 8128.52 | F14: 1446.76 | G14: 7613.62 | H14: 36670.35 | I14: 29056.73 | J14: 45962 | K14: 14 | L14: Bangalore-South
... A22: EMP0020 | B22: Operations | C22: Team Lead | D22: 36272.73 | E22: 10881.82 | F22: 341.81 | G22: 1193.18 | H22: 47496.36 | I22: 46303.18 | J22: 45962 | K22: 9 | L22: Mumbai-HO
A23: EMP0021 | B23: Finance | C23: Director | D23: 114497.32 | E23: 34349.2 | F23: 13657.45 | G23: 13216.45 | H23: 162503.97 | I23: 149287.52 | J23: 10/01/2025 | K23: 21 | L23: Delhi-North
A24: EMP0022 | B24: Marketing | C24: Manager | D24: 49525.45 | E24: 14857.63 | F24: 5479.75 | G24: 14002.29 | H24: 69862.83 | I24: 55860.54 | J24: 45962 | K24: 10 | L24: Bangalore-South
A25: EMP0023 | B25: Sales | C25: Associate | D25: 22908.31 | E25: 6872.49 | F25: 2460.22 | H25: 32241.02 | I25: 30407.27 | J25: 45962 | K25: 11 | L25: Chennai-South
A26: EMP0024 | B26: IT | C26: Associate | D26: 20113.2 | E26: 6033.96 | F26: 636.21 | G26: 19.58 | H26: 26783.37 | I26: 26763.79 | J26: 01-12-2025 | K26: 15 | L26: Kolkata-East
A27: EMP0025 | B27: Sales | C27: Analyst | D27: 34718.88 | E27: 10415.66 | F27: 5290.89 | G27: 5287.84 | H27: 50425.43 | I27: 45137.59 | J27: 45689 | K27: 19 | L27: Pune-West
A28: EMP0026 | B28: Customer Support | C28: Sr. Manager | D28: 72759.56 | E28: 21827.87 | F28: 9297.94 | G28: 13292.52 | H28: 103885.37 | I28: 90592.85 | J28: 45717 | K28: 12 | L28: Hyderabad-South
A29: EMP0027 | B29: IT | C29: Director | D29: 95815.77 | E29: 28744.73 | F29: 18272.06 | G29: 26515.12 | H29: 142832.56 | I29: 116317.44 | J29: 45658 | K29: 12 | L29: Chandigarh-North
A30: EMP0028 | B30: Operations | C30: Analyst | D30: 29886.06 | E30: 8965.82 | F30: 668.66 | G30: 3254.42 | H30: 39520.54 | I30: 36266.12 | J30: 45778 | K30: 13 | L30: Ahmedabad-West
A31: EMP0029 | B31: Finance | C31: Associate | D31: 19734.28 | E31: 5920.28 | F31: 2239.28 | G31: 466.26 | H31: 27893.84 | I31: 27427.58 | J31: 45992 | K31: 9 | L31: Jaipur-North
A32: EMP0030 | B32: Marketing | C32: Director | D32: 92491.65 | E32: 27747.49 | F32: 14069.87 | G32: 21249.99 | H32: 134309.01 | I32: 113059.02 | J32: 45717 | K32: 13 | L32: Mumbai-HO
A33: EMP0031 | B33: Sales | C33: Team Lead | D33: 48255.88 | E33: 14476.76 | F33: 1593.67 | G33: 7639.01 | H33: 64326.31 | I33: 56687.3 | J33: 45931 | K33: 17 | L33: Delhi-North
A34: EMP0032 | B34: Marketing | C34: Executive | D34: 30174.44 | E34: 9052.33 | F34: 4557.94 | G34: 6244.91 | H34: 43784.71 | I34: 37539.8 | J34: 45992 | K34: 5 | L34: Bangalore-South
A35: EMP0033 | B35: IT | C35: Team Lead | D35: 48932.09 | E35: 14679.63 | F35: 6359.98 | G35: 6431.15 | H35: 69971.7 | I35: 63540.55 | J35: 45901 | K35: 20 | L35: Chennai-South
A36: EMP0034 | B36: Marketing | C36: Associate | D36: 19784.92 | E36: 5935.48 | F36: 253.35 | G36: 124.85 | H36: 25973.75 | I36: 25848.9 | J36: 45901 | K36: 3 | L36: Kolkata-East
A37: EMP0035 | B37: Finance | C37: Manager | D37: 48963.91 | E37: 14689.17 | F37: 695.22 | G37: 9270.38 | H37: 64348.3 | I37: 55077.92 | J37: 45748 | K37: 8 | L37: Pune-West
A38: EMP0037 | B38: Marketing | C38: Executive | D38: 26745.26 | E38: 8023.58 | F38: 3869.25 | G38: 7079.87 | H38: 38638.09 | I38: 31558.22 | J38: 45931 | K38: 25 | L38: Chandigarh-North
... A41: EMP0040 | B41: Sales | C41: Sr. Manager | D41: 90588.3 | E41: 27176.49 | F41: 1783.1 | G41: 10941.83 | H41: 119547.89 | I41: 108606.06 | J41: 45809 | K41: 12 | L41: Mumbai-HO
A42: EMP0041 | B42: Customer Support | C42: Director | D42: 93933.69 | E42: 28180.11 | F42: 3599.35 | H42: 125713.15 | I42: 110600.56 | J42: 45717 | K42: 6 | L42: Delhi-North
A43: EMP0042 | B43: Marketing | C43: Executive | D43: 24451.2 | E43: 7335.36 | F43: 1221.61 | G43: 6772.49 | H43: 33008.17 | I43: 26235.68 | J43: 45870 | K43: 14 | L43: Bangalore-South
A44: EMP0043 | B44: Customer Support | C44: Director | D44: 120814.81 | E44: 36244.44 | F44: 2365.76 | G44: 23636.63 | H44: 159425.01 | I44: 135788.38 | J44: 45901 | K44: 5 | L44: Chennai-South
A45: EMP0044 | B45: Customer Support | C45: Associate | D45: 24976.77 | E45: 7493.03 | F45: 4627.53 | G45: 6359.3 | H45: 37097.33 | I45: 30738.03 | J45: 45717 | K45: 14 | L45: Kolkata-East
A46: EMP0045 | B46: Marketing | C46: Team Lead | D46: 41739.02 | E46: 12521.71 | F46: 7217.93 | G46: 11300.12 | H46: 61478.66 | I46: 50178.54 | J46: 45717 | K46: 10 | L46: Pune-West
A47: EMP0046 | B47: Marketing | C47: Associate | D47: 25094.22 | E47: 7528.27 | F47: 1331.01 | G47: 5902.69 | H47: 33953.5 | I47: 28050.81 | J47: 45870 | K47: 12 | L47: Hyderabad-South
A48: EMP0047 | B48: IT | C48: Team Lead | D48: 44752.28 | E48: 13425.68 | F48: 6538.36 | G48: 10517.16 | H48: 64716.32 | I48: 54199.16 | J48: Nov 2025 | K48: 13 | L48: Chandigarh-North
A49: EMP0048 | B49: Sales | C49: Team Lead | D49: 37167.16 | E49: 11150.15 | F49: 2205.56 | G49: 10801.25 | H49: 50522.87 | I49: 39721.62 | J49: 45931 | K49: 21 | L49: Ahmedabad-West
A50: EMP0049 | B50: Sales | C50: Manager | D50: 46097.24 | E50: 13829.17 | F50: 2891.26 | G50: 693.43 | H50: 62817.67 | I50: 62124.24 | J50: 45870 | K50: 16 | L50: Jaipur-North
...

Sheet Clean_Data
A2: Employee ID | B2: Department | C2: Designation | D2: Basic Pay | E2: Allowances | F2: Overtime Amount | G2: Deductions | H2: Gross Salary | I2: Net Salary | J2: Pay Month | K2: Experience | L2: Destination | M2: Duplicate_Flag | N2: Validation
A3: =Raw_Data!A3 -> EMP0001 | B3: =TRIM(CLEAN(Raw_Data!B3)) -> Sales | C3: Associate | D3: =IF(ISBLANK(Raw_Data!D3),AVERAGE(Raw_Data!D$2:D$5002),Raw_Data!D3) -> 18180.08 | E3: =IF(ISBLANK(Raw_Data!E3),AVERAGE(Raw_Data!E$2:E$5002),Raw_Data!E3) -> 5454.02 | F3: =IF(ISBLANK(Raw_Data!F3),AVERAGE(Raw_Data!F$2:F$5002),Raw_Data!F3) -> 1000.01 | G3: =IF(ISBLANK(Raw_Data!G3),AVERAGE(Raw_Data!G$2:G$5002),Raw_Data!G3) -> 1217.40 | H3: =ROUND(D3+E3+F3,0) -> 24634.00 | I3: =+ROUND(H3-G3,0) -> 23417.00 | J3: =TEXT(Raw_Data!J3,"MMM-YYY") -> Dec-2025 | K3: =Raw_Data!K3 -> 14 | L3: =Raw_Data!L3 -> Delhi-North | M3: =IF(COUNTIF($A$3:A3,A3)>1,"Duplicate","OK") -> OK | N3: =IF(AND( H3=ROUND(D3+E3+F3,0), I3=ROUND(H3-G3,0), I3>=0 ),"VALID","ERROR") -> VALID
A4: =Raw_Data!A4 -> EMP0002 | B4: =TRIM(CLEAN(Raw_Data!B4)) -> HR | C4: Sr. Manager | D4: =IF(ISBLANK(Raw_Data!D4),AVERAGE(Raw_Data!D$2:D$5002),Raw_Data!D4) -> 84257.36 | E4: =IF(ISBLANK(Raw_Data!E4),AVERAGE(Raw_Data!E$2:E$5002),Raw_Data!E4) -> 25277.21 | F4: =IF(ISBLANK(Raw_Data!F4),AVERAGE(Raw_Data!F$2:F$5002),Raw_Data!F4) -> 9190.23 | G4: =IF(ISBLANK(Raw_Data!G4),AVERAGE(Raw_Data!G$2:G$5002),Raw_Data!G4) -> 14926.00 | H4: =ROUND(D4+E4+F4,0) -> 118725.00 | I4: =+ROUND(H4-G4,0) -> 103799.00 | J4: =TEXT(Raw_Data!J4,"MMM-YYY") -> Jan-2025 | K4: =Raw_Data!K4 -> 2 | L4: =Raw_Data!L4 -> Bangalore-South | M4: =IF(COUNTIF($A$3:A4,A4)>1,"Duplicate","OK") -> OK | N4: =IF(AND( H4=ROUND(D4+E4+F4,0), I4=ROUND(H4-G4,0), I4>=0 ),"VALID","ERROR") -> VALID
A5: =Raw_Data!A5 -> EMP0003 | B5: =TRIM(CLEAN(Raw_Data!B5)) -> HR | C5: Associate | D5: =IF(ISBLANK(Raw_Data!D5),AVERAGE(Raw_Data!D$2:D$5002),Raw_Data!D5) -> 19574.19 | E5: =IF(ISBLANK(Raw_Data!E5),AVERAGE(Raw_Data!E$2:E$5002),Raw_Data!E5) -> 5872.26 | F5: =IF(ISBLANK(Raw_Data!F5),AVERAGE(Raw_Data!F$2:F$5002),Raw_Data!F5) -> 1978.38 | G5: =IF(ISBLANK(Raw_Data!G5),AVERAGE(Raw_Data!G$2:G$5002),Raw_Data!G5) -> 155.83 | H5: =ROUND(D5+E5+F5,0) -> 27425.00 | I5: =+ROUND(H5-G5,0) -> 27269.00 | J5: =TEXT(Raw_Data!J5,"MMM-YYY") -> Apr-2025 | K5: =Raw_Data!K5 -> 4 | L5: =Raw_Data!L5 -> Chennai-South | M5: =IF(COUNTIF($A$3:A5,A5)>1,"Duplicate","OK") -> OK | N5: =IF(AND( H5=ROUND(D5+E5+F5,0), I5=ROUND(H5-G5,0), I5>=0 ),"VALID","ERROR") -> VALID
A6: =Raw_Data!A6 -> EMP0004 | B6: =TRIM(CLEAN(Raw_Data!B6)) -> Sales | C6: Sr. Manager | D6: =IF(ISBLANK(Raw_Data!D6),AVERAGE(Raw_Data!D$2:D$5002),Raw_Data!D6) -> 83234.45 | E6: =IF(ISBLANK(Raw_Data!E6),AVERAGE(Raw_Data!E$2:E$5002),Raw_Data!E6) -> 24970.33 | F6: =IF(ISBLANK(Raw_Data!F6),AVERAGE(Raw_Data!F$2:F$5002),Raw_Data!F6) -> 6983.70 | G6: =IF(ISBLANK(Raw_Data!G6),AVERAGE(Raw_Data!G$2:G$5002),Raw_Data!G6) -> 11216.90 | H6: =ROUND(D6+E6+F6,0) -> 115188.00 | I6: =+ROUND(H6-G6,0) -> 103971.00 | J6: =TEXT(Raw_Data!J6,"MMM-YYY") -> May-2025 | K6: =Raw_Data!K6 -> 17 | L6: =Raw_Data!L6 -> Kolkata-East | M6: =IF(COUNTIF($A$3:A6,A6)>1,"Duplicate","OK") -> OK | N6: =IF(AND( H6=ROUND(D6+E6+F6,0), I6=ROUND(H6-G6,0), I6>=0 ),"VALID","ERROR") -> VALID
A7: =Raw_Data!A7 -> EMP0005 | B7: =TRIM(CLEAN(Raw_Data!B7)) -> Customer Support | C7: Director | D7: =IF(ISBLANK(Raw_Data!D7),AVERAGE(Raw_Data!D$2:D$5002),Raw_Data!D7) -> 90233.96 | E7: =IF(ISBLANK(Raw_Data!E7),AVERAGE(Raw_Data!E$2:E$5002),Raw_Data!E7) -> 27070.19 | F7: =IF(ISBLANK(Raw_Data!F7),AVERAGE(Raw_Data!F$2:F$5002),Raw_Data!F7) -> 14542.45 | G7: =IF(ISBLANK(Raw_Data!G7),AVERAGE(Raw_Data!G$2:G$5002),Raw_Data!G7) -> 18898.76 | H7: =ROUND(D7+E7+F7,0) -> 131847.00 | I7: =+ROUND(H7-G7,0) -> 112948.00 | J7: =TEXT(Raw_Data!J7,"MMM-YYY") -> Jun-2025 | K7: =Raw_Data!K7 -> 23 | L7: =Raw_Data!L7 -> Pune-West | M7: =IF(COUNTIF($A$3:A7,A7)>1,"Duplicate","OK") -> OK | N7: =IF(AND( H7=ROUND(D7+E7+F7,0), I7=ROUND(H7-G7,0), I7>=0 ),"VALID","ERROR") -> VALID
A8: =Raw_Data!A8 -> EMP0006 | B8: =TRIM(CLEAN(Raw_Data!B8)) -> IT | C8: Executive | D8: =IF(ISBLANK(Raw_Data!D8),AVERAGE(Raw_Data!D$2:D$5002),Raw_Data!D8) -> 23894.76 | E8: =IF(ISBLANK(Raw_Data!E8),AVERAGE(Raw_Data!E$2:E$5002),Raw_Data!E8) -> 7168.43 | F8: =IF(ISBLANK(Raw_Data!F8),AVERAGE(Raw_Data!F$2:F$5002),Raw_Data!F8) -> 3648.70 | G8: =IF(ISBLANK(Raw_Data!G8),AVERAGE(Raw_Data!G$2:G$5002),Raw_Data!G8) -> 732.69 | H8: =ROUND(D8+E8+F8,0) -> 34712.00 | I8: =+ROUND(H8-G8,0) -> 33979.00 | J8: =TEXT(Raw_Data!J8,"MMM-YYY") -> Jul-2025 | K8: =Raw_Data!K8 -> 2 | L8: =Raw_Data!L8 -> Hyderabad-South | M8: =IF(COUNTIF($A$3:A8,A8)>1,"Duplicate","OK") -> OK | N8: =IF(AND( H8=ROUND(D8+E8+F8,0), I8=ROUND(H8-G8,0), I8>=0 ),"VALID","ERROR") -> VALID
A9: =Raw_Data!A9 -> EMP0007 | B9: =TRIM(CLEAN(Raw_Data!B9)) -> HR | C9: Analyst | D9: =IF(ISBLANK(Raw_Data!D9),AVERAGE(Raw_Data!D$2:D$5002),Raw_Data!D9) -> 33474.94 | E9: =IF(ISBLANK(Raw_Data!E9),AVERAGE(Raw_Data!E$2:E$5002),Raw_Data!E9) -> 10042.48 | F9: =IF(ISBLANK(Raw_Data!F9),AVERAGE(Raw_Data!F$2:F$5002),Raw_Data!F9) -> 4041.94 | G9: =IF(ISBLANK(Raw_Data!G9),AVERAGE(Raw_Data!G$2:G$5002),Raw_Data!G9) -> 8105.57 | H9: =ROUND(D9+E9+F9,0) -> 47559.00 | I9: =+ROUND(H9-G9,0) -> 39453.00 | J9: =TEXT(Raw_Data!J9,"MMM-YYY") -> Dec-2025 | K9: =Raw_Data!K9 -> 25 | L9: =Raw_Data!L9 -> Chandigarh-North | M9: =IF(COUNTIF($A$3:A9,A9)>1,"Duplicate","OK") -> OK | N9: =IF(AND( H9=ROUND(D9+E9+F9,0), I9=ROUND(H9-G9,0), I9>=0 ),"VALID","ERROR") -> VALID
A10: =Raw_Data!A10 -> EMP0008 | B10: =TRIM(CLEAN(Raw_Data!B10)) -> Marketing | C10: Manager | D10: =IF(ISBLANK(Raw_Data!D10),AVERAGE(Raw_Data!D$2:D$5002),Raw_Data!D10) -> 47246.87 | E10: =IF(ISBLANK(Raw_Data!E10),AVERAGE(Raw_Data!E$2:E$5002),Raw_Data!E10) -> 14174.06 | F10: =IF(ISBLANK(Raw_Data!F10),AVERAGE(Raw_Data!F$2:F$5002),Raw_Data!F10) -> 8715.11 | G10: =IF(ISBLANK(Raw_Data!G10),AVERAGE(Raw_Data!G$2:G$5002),Raw_Data!G10) -> 1116.92 | H10: =ROUND(D10+E10+F10,0) -> 70136.00 | I10: =+ROUND(H10-G10,0) -> 69019.00 | J10: =TEXT(Raw_Data!J10,"MMM-YYY") -> May-2025 | K10: =Raw_Data!K10 -> 18 | L10: =Raw_Data!L10 -> Ahmedabad-West | M10: =IF(COUNTIF($A$3:A10,A10)>1,"Duplicate","OK") -> OK | N10: =IF(AND( H10=ROUND(D10+E10+F10,0), I10=ROUND(H10-G10,0), I10>=0 ),"VALID","ERROR") -> VALID
A11: =Raw_Data!A11 -> EMP0009 | B11: =TRIM(CLEAN(Raw_Data!B11)) -> Customer Support | C11: Sr. Manager | D11: =IF(ISBLANK(Raw_Data!D11),AVERAGE(Raw_Data!D$2:D$5002),Raw_Data!D11) -> 81081.51 | E11: =IF(ISBLANK(Raw_Data!E11),AVERAGE(Raw_Data!E$2:E$5002),Raw_Data!E11) -> 24324.45 | F11: =IF(ISBLANK(Raw_Data!F11),AVERAGE(Raw_Data!F$2:F$5002),Raw_Data!F11) -> 13973.70 | G11: =IF(ISBLANK(Raw_Data!G11),AVERAGE(Raw_Data!G$2:G$5002),Raw_Data!G11) -> 14043.78 | H11: =ROUND(D11+E11+F11,0) -> 119380.00 | I11: =+ROUND(H11-G11,0) -> 105336.00 | J11: =TEXT(Raw_Data!J11,"MMM-YYY") -> Dec-2025 | K11: =Raw_Data!K11 -> 4 | L11: =Raw_Data!L11 -> Jaipur-North | M11: =IF(COUNTIF($A$3:A11,A11)>1,"Duplicate","OK") -> OK | N11: =IF(AND( H11=ROUND(D11+E11+F11,0), I11=ROUND(H11-G11,0), I11>=0 ),"VALID","ERROR") -> VALID
A12: =Raw_Data!A12 -> EMP0010 | B12: =TRIM(CLEAN(Raw_Data!B12)) -> HR | C12: Associate | D12: =IF(ISBLANK(Raw_Data!D12),AVERAGE(Raw_Data!D$2:D$5002),Raw_Data!D12) -> 22761.10 | E12: =IF(ISBLANK(Raw_Data!E12),AVERAGE(Raw_Data!E$2:E$5002),Raw_Data!E12) -> 6828.33 | F12: =IF(ISBLANK(Raw_Data!F12),AVERAGE(Raw_Data!F$2:F$5002),Raw_Data!F12) -> 3519.18 | G12: =IF(ISBLANK(Raw_Data!G12),AVERAGE(Raw_Data!G$2:G$5002),Raw_Data!G12) -> 6727.42 | H12: =ROUND(D12+E12+F12,0) -> 33109.00 | I12: =+ROUND(H12-G12,0) -> 26382.00 | J12: =TEXT(Raw_Data!J12,"MMM-YYY") -> Apr-2025 | K12: =Raw_Data!K12 -> 18 | L12: =Raw_Data!L12 -> Mumbai-HO | M12: =IF(COUNTIF($A$3:A12,A12)>1,"Duplicate","OK") -> OK | N12: =IF(AND( H12=ROUND(D12+E12+F12,0), I12=ROUND(H12-G12,0), I12>=0 ),"VALID","ERROR") -> VALID
A13: =Raw_Data!A13 -> EMP0011 | B13: =TRIM(CLEAN(Raw_Data!B13)) -> Customer Support | C13: Associate | D13: =IF(ISBLANK(Raw_Data!D13),AVERAGE(Raw_Data!D$2:D$5002),Raw_Data!D13) -> 20736.91 | E13: =IF(ISBLANK(Raw_Data!E13),AVERAGE(Raw_Data!E$2:E$5002),Raw_Data!E13) -> 6221.07 | F13: =IF(ISBLANK(Raw_Data!F13),AVERAGE(Raw_Data!F$2:F$5002),Raw_Data!F13) -> 1880.47 | G13: =IF(ISBLANK(Raw_Data!G13),AVERAGE(Raw_Data!G$2:G$5002),Raw_Data!G13) -> 5189.06 | H13: =ROUND(D13+E13+F13,0) -> 28838.00 | I13: =+ROUND(H13-G13,0) -> 23649.00 | J13: =TEXT(Raw_Data!J13,"MMM-YYY") -> Mar-2025 | K13: =Raw_Data!K13 -> 18 | L13: =Raw_Data!L13 -> Delhi-North | M13: =IF(COUNTIF($A$3:A13,A13)>1,"Duplicate","OK") -> OK | N13: =IF(AND( H13=ROUND(D13+E13+F13,0), I13=ROUND(H13-G13,0), I13>=0 ),"VALID","ERROR") -> VALID
A14: =Raw_Data!A14 -> EMP0012 | B14: =TRIM(CLEAN(Raw_Data!B14)) -> IT | C14: Analyst | D14: =IF(ISBLANK(Raw_Data!D14),AVERAGE(Raw_Data!D$2:D$5002),Raw_Data!D14) -> 27095.07 | E14: =IF(ISBLANK(Raw_Data!E14),AVERAGE(Raw_Data!E$2:E$5002),Raw_Data!E14) -> 8128.52 | F14: =IF(ISBLANK(Raw_Data!F14),AVERAGE(Raw_Data!F$2:F$5002),Raw_Data!F14) -> 1446.76 | G14: =IF(ISBLANK(Raw_Data!G14),AVERAGE(Raw_Data!G$2:G$5002),Raw_Data!G14) -> 7613.62 | H14: =ROUND(D14+E14+F14,0) -> 36670.00 | I14: =+ROUND(H14-G14,0) -> 29056.00 | J14: =TEXT(Raw_Data!J14,"MMM-YYY") -> Nov-2025 | K14: =Raw_Data!K14 -> 14 | L14: =Raw_Data!L14 -> Bangalore-South | M14: =IF(COUNTIF($A$3:A14,A14)>1,"Duplicate","OK") -> OK | N14: =IF(AND( H14=ROUND(D14+E14+F14,0), I14=ROUND(H14-G14,0), I14>=0 ),"VALID","ERROR") -> VALID
... A54: =Raw_Data!A54 -> EMP0053 | B54: =TRIM(CLEAN(Raw_Data!B54)) -> Operations | C54: Manager | D54: =IF(ISBLANK(Raw_Data!D54),AVERAGE(Raw_Data!D$2:D$5002),Raw_Data!D54) -> 50694.66 | E54: =IF(ISBLANK(Raw_Data!E54),AVERAGE(Raw_Data!E$2:E$5002),Raw_Data!E54) -> 15208.40 | F54: =IF(ISBLANK(Raw_Data!F54),AVERAGE(Raw_Data!F$2:F$5002),Raw_Data!F54) -> 2643.89 | G54: =IF(ISBLANK(Raw_Data!G54),AVERAGE(Raw_Data!G$2:G$5002),Raw_Data!G54) -> 10185.46 | H54: =ROUND(D54+E54+F54,0) -> 68547.00 | I54: =+ROUND(H54-G54,0) -> 58362.00 | J54: =TEXT(Raw_Data!J54,"MMM-YYY") -> Jun-2025 | K54: =Raw_Data!K54 -> 12 | L54: =Raw_Data!L54 -> Chennai-South | M54: =IF(COUNTIF($A$3:A54,A54)>1,"Duplicate","OK") -> OK | N54: =IF(AND( H54=ROUND(D54+E54+F54,0), I54=ROUND(H54-G54,0), I54>=0 ),"VALID","ERROR") -> VALID
A55: =Raw_Data!A55 -> EMP0054 | B55: Finance | C55: Analyst | D55: =IF(ISBLANK(Raw_Data!D55),AVERAGE(Raw_Data!D$2:D$5002),Raw_Data!D55) -> 28957.86 | E55: =IF(ISBLANK(Raw_Data!E55),AVERAGE(Raw_Data!E$2:E$5002),Raw_Data!E55) -> 8687.36 | F55: =IF(ISBLANK(Raw_Data!F55),AVERAGE(Raw_Data!F$2:F$5002),Raw_Data!F55) -> 3890.14 | G55: =IF(ISBLANK(Raw_Data!G55),AVERAGE(Raw_Data!G$2:G$5002),Raw_Data!G55) -> 2606.18 | H55: =ROUND(D55+E55+F55,0) -> 41535.00 | I55: =+ROUND(H55-G55,0) -> 38929.00 | J55: =TEXT(Raw_Data!J55,"MMM-YYY") -> Jun-2025 | K55: =Raw_Data!K55 -> 5 | L55: =Raw_Data!L55 -> Kolkata-East | M55: =IF(COUNTIF($A$3:A55,A55)>1,"Duplicate","OK") -> OK | N55: =IF(AND( H55=ROUND(D55+E55+F55,0), I55=ROUND(H55-G55,0), I55>=0 ),"VALID","ERROR") -> VALID
A56: =Raw_Data!A56 -> EMP0055 | B56: =TRIM(CLEAN(Raw_Data!B56)) -> Customer Support | C56: Associate | D56: =IF(ISBLANK(Raw_Data!D56),AVERAGE(Raw_Data!D$2:D$5002),Raw_Data!D56) -> 71831.17 | E56: =IF(ISBLANK(Raw_Data!E56),AVERAGE(Raw_Data!E$2:E$5002),Raw_Data!E56) -> 5420.12 | F56: =IF(ISBLANK(Raw_Data!F56),AVERAGE(Raw_Data!F$2:F$5002),Raw_Data!F56) -> 2244.51 | G56: =IF(ISBLANK(Raw_Data!G56),AVERAGE(Raw_Data!G$2:G$5002),Raw_Data!G56) -> 3051.49 | H56: =ROUND(D56+E56+F56,0) -> 79496.00 | I56: =+ROUND(H56-G56,0) -> 76445.00 | J56: =TEXT(Raw_Data!J56,"MMM-YYY") -> Feb-2025 | K56: =Raw_Data!K56 -> 2 | L56: =Raw_Data!L56 -> Pune-West | M56: =IF(COUNTIF($A$3:A56,A56)>1,"Duplicate","OK") -> OK | N56: =IF(AND( H56=ROUND(D56+E56+F56,0), I56=ROUND(H56-G56,0), I56>=0 ),"VALID","ERROR") -> VALID
A57: =Raw_Data!A57 -> EMP0056 | B57: =TRIM(CLEAN(Raw_Data!B57)) -> HR | C57: Manager | D57: =IF(ISBLANK(Raw_Data!D57),AVERAGE(Raw_Data!D$2:D$5002),Raw_Data!D57) -> 48836.78 | E57: =IF(ISBLANK(Raw_Data!E57),AVERAGE(Raw_Data!E$2:E$5002),Raw_Data!E57) -> 14651.03 | F57: =IF(ISBLANK(Raw_Data!F57),AVERAGE(Raw_Data!F$2:F$5002),Raw_Data!F57) -> 2590.31 | G57: =IF(ISBLANK(Raw_Data!G57),AVERAGE(Raw_Data!G$2:G$5002),Raw_Data!G57) -> 13673.21 | H57: =ROUND(D57+E57+F57,0) -> 66078.00 | I57: =+ROUND(H57-G57,0) -> 52405.00 | J57: =TEXT(Raw_Data!J57,"MMM-YYY") -> Feb-2025 | K57: =Raw_Data!K57 -> 24 | L57: =Raw_Data!L57 -> Hyderabad-South | M57: =IF(COUNTIF($A$3:A57,A57)>1,"Duplicate","OK") -> OK | N57: =IF(AND( H57=ROUND(D57+E57+F57,0), I57=ROUND(H57-G57,0), I57>=0 ),"VALID","ERROR") -> VALID
A58: =Raw_Data!A58 -> EMP0057 | B58: =TRIM(CLEAN(Raw_Data!B58)) -> Finance | C58: Analyst | D58: =IF(ISBLANK(Raw_Data!D58),AVERAGE(Raw_Data!D$2:D$5002),Raw_Data!D58) -> 27849.87 | E58: =IF(ISBLANK(Raw_Data!E58),AVERAGE(Raw_Data!E$2:E$5002),Raw_Data!E58) -> 8354.96 | F58: =IF(ISBLANK(Raw_Data!F58),AVERAGE(Raw_Data!F$2:F$5002),Raw_Data!F58) -> 2440.68 | G58: =IF(ISBLANK(Raw_Data!G58),AVERAGE(Raw_Data!G$2:G$5002),Raw_Data!G58) -> 4538.56 | H58: =ROUND(D58+E58+F58,0) -> 38646.00 | I58: =+ROUND(H58-G58,0) -> 34107.00 | J58: =TEXT(Raw_Data!J58,"MMM-YYY") -> May-2025 | K58: =Raw_Data!K58 -> 16 | L58: =Raw_Data!L58 -> Chandigarh-North | M58: =IF(COUNTIF($A$3:A58,A58)>1,"Duplicate","OK") -> OK | N58: =IF(AND( H58=ROUND(D58+E58+F58,0), I58=ROUND(H58-G58,0), I58>=0 ),"VALID","ERROR") -> VALID
A59: =Raw_Data!A59 -> EMP0058 | B59: =TRIM(CLEAN(Raw_Data!B59)) -> Operations | C59: Director | D59: =IF(ISBLANK(Raw_Data!D59),AVERAGE(Raw_Data!D$2:D$5002),Raw_Data!D59) -> 113543.15 | E59: =IF(ISBLANK(Raw_Data!E59),AVERAGE(Raw_Data!E$2:E$5002),Raw_Data!E59) -> 34062.94 | F59: =IF(ISBLANK(Raw_Data!F59),AVERAGE(Raw_Data!F$2:F$5002),Raw_Data!F59) -> 177.65 | G59: =IF(ISBLANK(Raw_Data!G59),AVERAGE(Raw_Data!G$2:G$5002),Raw_Data!G59) -> 27832.97 | H59: =ROUND(D59+E59+F59,0) -> 147784.00 | I59: =+ROUND(H59-G59,0) -> 119951.00 | J59: =TEXT(Raw_Data!J59,"MMM-YYY") -> May-2025 | K59: =Raw_Data!K59 -> 6 | L59: =Raw_Data!L59 -> Ahmedabad-West | M59: =IF(COUNTIF($A$3:A59,A59)>1,"Duplicate","OK") -> OK | N59: =IF(AND( H59=ROUND(D59+E59+F59,0), I59=ROUND(H59-G59,0), I59>=0 ),"VALID","ERROR") -> VALID
A60: =Raw_Data!A60 -> EMP0059 | B60: =TRIM(CLEAN(Raw_Data!B60)) -> Sales | C60: Associate | D60: =IF(ISBLANK(Raw_Data!D60),AVERAGE(Raw_Data!D$2:D$5002),Raw_Data!D60) -> 24760.30 | E60: =IF(ISBLANK(Raw_Data!E60),AVERAGE(Raw_Data!E$2:E$5002),Raw_Data!E60) -> 7428.09 | F60: =IF(ISBLANK(Raw_Data!F60),AVERAGE(Raw_Data!F$2:F$5002),Raw_Data!F60) -> 665.02 | G60: =IF(ISBLANK(Raw_Data!G60),AVERAGE(Raw_Data!G$2:G$5002),Raw_Data!G60) -> 857.41 | H60: =ROUND(D60+E60+F60,0) -> 32853.00 | I60: =+ROUND(H60-G60,0) -> 31996.00 | J60: =TEXT(Raw_Data!J60,"MMM-YYY") -> Feb-2025 | K60: =Raw_Data!K60 -> 25 | L60: =Raw_Data!L60 -> Jaipur-North | M60: =IF(COUNTIF($A$3:A60,A60)>1,"Duplicate","OK") -> OK | N60: =IF(AND( H60=ROUND(D60+E60+F60,0), I60=ROUND(H60-G60,0), I60>=0 ),"VALID","ERROR") -> VALID
A61: =Raw_Data!A61 -> EMP0060 | B61: =TRIM(CLEAN(Raw_Data!B61)) -> Sales | C61: Manager | D61: =IF(ISBLANK(Raw_Data!D61),AVERAGE(Raw_Data!D$2:D$5002),Raw_Data!D61) -> 47798.06 | E61: =IF(ISBLANK(Raw_Data!E61),AVERAGE(Raw_Data!E$2:E$5002),Raw_Data!E61) -> 14339.42 | F61: =IF(ISBLANK(Raw_Data!F61),AVERAGE(Raw_Data!F$2:F$5002),Raw_Data!F61) -> 2693.48 | G61: =IF(ISBLANK(Raw_Data!G61),AVERAGE(Raw_Data!G$2:G$5002),Raw_Data!G61) -> 3020.31 | H61: =ROUND(D61+E61+F61,0) -> 64831.00 | I61: =+ROUND(H61-G61,0) -> 61811.00 | J61: =TEXT(Raw_Data!J61,"MMM-YYY") -> Jun-2025 | K61: =Raw_Data!K61 -> 18 | L61: =Raw_Data!L61 -> Mumbai-HO | M61: =IF(COUNTIF($A$3:A61,A61)>1,"Duplicate","OK") -> OK | N61: =IF(AND( H61=ROUND(D61+E61+F61,0), I61=ROUND(H61-G61,0), I61>=0 ),"VALID","ERROR") -> VALID
A62: =Raw_Data!A62 -> EMP0061 | B62: =TRIM(CLEAN(Raw_Data!B62)) -> Finance | C62: Sr. Manager | D62: =IF(ISBLANK(Raw_Data!D62),AVERAGE(Raw_Data!D$2:D$5002),Raw_Data!D62) -> 81490.19 | E62: =IF(ISBLANK(Raw_Data!E62),AVERAGE(Raw_Data!E$2:E$5002),Raw_Data!E62) -> 24447.06 | F62: =IF(ISBLANK(Raw_Data!F62),AVERAGE(Raw_Data!F$2:F$5002),Raw_Data!F62) -> 4302.42 | G62: =IF(ISBLANK(Raw_Data!G62),AVERAGE(Raw_Data!G$2:G$5002),Raw_Data!G62) -> 11943.17 | H62: =ROUND(D62+E62+F62,0) -> 110240.00 | I62: =+ROUND(H62-G62,0) -> 98297.00 | J62: =TEXT(Raw_Data!J62,"MMM-YYY") -> Jan-2025 | K62: =Raw_Data!K62 -> 11 | L62: =Raw_Data!L62 -> Delhi-North | M62: =IF(COUNTIF($A$3:A62,A62)>1,"Duplicate","OK") -> OK | N62: =IF(AND( H62=ROUND(D62+E62+F62,0), I62=ROUND(H62-G62,0), I62>=0 ),"VALID","ERROR") -> VALID
A63: =Raw_Data!A63 -> EMP0062 | B63: =TRIM(CLEAN(Raw_Data!B63)) -> HR | C63: Sr. Manager | D63: =IF(ISBLANK(Raw_Data!D63),AVERAGE(Raw_Data!D$2:D$5002),Raw_Data!D63) -> 76012.97 | E63: =IF(ISBLANK(Raw_Data!E63),AVERAGE(Raw_Data!E$2:E$5002),Raw_Data!E63) -> 22803.89 | F63: =IF(ISBLANK(Raw_Data!F63),AVERAGE(Raw_Data!F$2:F$5002),Raw_Data!F63) -> 4206.26 | G63: =IF(ISBLANK(Raw_Data!G63),AVERAGE(Raw_Data!G$2:G$5002),Raw_Data!G63) -> 80.86 | H63: =ROUND(D63+E63+F63,0) -> 103023.00 | I63: =+ROUND(H63-G63,0) -> 102942.00 | J63: =TEXT(Raw_Data!J63,"MMM-YYY") -> Mar-2025 | K63: =Raw_Data!K63 -> 4 | L63: =Raw_Data!L63 -> Bangalore-South | M63: =IF(COUNTIF($A$3:A63,A63)>1,"Duplicate","OK") -> OK | N63: =IF(AND( H63=ROUND(D63+E63+F63,0), I63=ROUND(H63-G63,0), I63>=0 ),"VALID","ERROR") -> VALID
A64: =Raw_Data!A64 -> EMP0063 | B64: =TRIM(CLEAN(Raw_Data!B64)) -> Sales | C64: Analyst | D64: =IF(ISBLANK(Raw_Data!D64),AVERAGE(Raw_Data!D$2:D$5002),Raw_Data!D64) -> 26615.82 | E64: =IF(ISBLANK(Raw_Data!E64),AVERAGE(Raw_Data!E$2:E$5002),Raw_Data!E64) -> 7984.75 | F64: =IF(ISBLANK(Raw_Data!F64),AVERAGE(Raw_Data!F$2:F$5002),Raw_Data!F64) -> 2351.96 | G64: =IF(ISBLANK(Raw_Data!G64),AVERAGE(Raw_Data!G$2:G$5002),Raw_Data!G64) -> 5634.58 | H64: =ROUND(D64+E64+F64,0) -> 36953.00 | I64: =+ROUND(H64-G64,0) -> 31318.00 | J64: =TEXT(Raw_Data!J64,"MMM-YYY") -> Sep-2025 | K64: =Raw_Data!K64 -> 24 | L64: =Raw_Data!L64 -> Chennai-South | M64: =IF(COUNTIF($A$3:A64,A64)>1,"Duplicate","OK") -> OK | N64: =IF(AND( H64=ROUND(D64+E64+F64,0), I64=ROUND(H64-G64,0), I64>=0 ),"VALID","ERROR") -> VALID
A65: =Raw_Data!A65 -> EMP0064 | B65: =TRIM(CLEAN(Raw_Data!B65)) -> HR | C65: Associate | D65: =IF(ISBLANK(Raw_Data!D65),AVERAGE(Raw_Data!D$2:D$5002),Raw_Data!D65) -> 18541.76 | E65: =IF(ISBLANK(Raw_Data!E65),AVERAGE(Raw_Data!E$2:E$5002),Raw_Data!E65) -> 5562.53 | F65: =IF(ISBLANK(Raw_Data!F65),AVERAGE(Raw_Data!F$2:F$5002),Raw_Data!F65) -> 3274.87 | G65: =IF(ISBLANK(Raw_Data!G65),AVERAGE(Raw_Data!G$2:G$5002),Raw_Data!G65) -> 5028.13 | H65: =ROUND(D65+E65+F65,0) -> 27379.00 | I65: =+ROUND(H65-G65,0) -> 22351.00 | J65: =TEXT(Raw_Data!J65,"MMM-YYY") -> Sep-2025 | K65: =Raw_Data!K65 -> 22 | L65: =Raw_Data!L65 -> Kolkata-East | M65: =IF(COUNTIF($A$3:A65,A65)>1,"Duplicate","OK") -> OK | N65: =IF(AND( H65=ROUND(D65+E65+F65,0), I65=ROUND(H65-G65,0), I65>=0 ),"VALID","ERROR") -> VALID
A66: =Raw_Data!A66 -> EMP0065 | B66: =TRIM(CLEAN(Raw_Data!B66)) -> HR | C66: Director | D66: =IF(ISBLANK(Raw_Data!D66),AVERAGE(Raw_Data!D$2:D$5002),Raw_Data!D66) -> 103291.78 | E66: =IF(ISBLANK(Raw_Data!E66),AVERAGE(Raw_Data!E$2:E$5002),Raw_Data!E66) -> 30987.53 | F66: =IF(ISBLANK(Raw_Data!F66),AVERAGE(Raw_Data!F$2:F$5002),Raw_Data!F66) -> 11414.26 | G66: =IF(ISBLANK(Raw_Data!G66),AVERAGE(Raw_Data!G$2:G$5002),Raw_Data!G66) -> 13318.03 | H66: =ROUND(D66+E66+F66,0) -> 145694.00 | I66: =+ROUND(H66-G66,0) -> 132376.00 | J66: =TEXT(Raw_Data!J66,"MMM-YYY") -> Jan-2025 | K66: =Raw_Data!K66 -> 7 | L66: =Raw_Data!L66 -> Pune-West | M66: =IF(COUNTIF($A$3:A66,A66)>1,"Duplicate","OK") -> OK | N66: =IF(AND( H66=ROUND(D66+E66+F66,0), I66=ROUND(H66-G66,0), I66>=0 ),"VALID","ERROR") -> VALID
A67: =Raw_Data!A67 -> EMP0066 | B67: =TRIM(CLEAN(Raw_Data!B67)) -> IT | C67: Analyst | D67: =IF(ISBLANK(Raw_Data!D67),AVERAGE(Raw_Data!D$2:D$5002),Raw_Data!D67) -> 33989.81 | E67: =IF(ISBLANK(Raw_Data!E67),AVERAGE(Raw_Data!E$2:E$5002),Raw_Data!E67) -> 10196.94 | F67: =IF(ISBLANK(Raw_Data!F67),AVERAGE(Raw_Data!F$2:F$5002),Raw_Data!F67) -> 5412.01 | G67: =IF(ISBLANK(Raw_Data!G67),AVERAGE(Raw_Data!G$2:G$5002),Raw_Data!G67) -> 8776.54 | H67: =ROUND(D67+E67+F67,0) -> 49599.00 | I67: =+ROUND(H67-G67,0) -> 40822.00 | J67: =TEXT(Raw_Data!J67,"MMM-YYY") -> Jun-2025 | K67: =Raw_Data!K67 -> 20 | L67: =Raw_Data!L67 -> Hyderabad-South | M67: =IF(COUNTIF($A$3:A67,A67)>1,"Duplicate","OK") -> OK | N67: =IF(AND( H67=ROUND(D67+E67+F67,0), I67=ROUND(H67-G67,0), I67>=0 ),"VALID","ERROR") -> VALID
... A123: =Raw_Data!A123 -> EMP0124 | B123: =TRIM(CLEAN(Raw_Data!B123)) -> Marketing | C123: Director | D123: =IF(ISBLANK(Raw_Data!D123),AVERAGE(Raw_Data!D$2:D$5002),Raw_Data!D123) -> 101700.51 | E123: =IF(ISBLANK(Raw_Data!E123),AVERAGE(Raw_Data!E$2:E$5002),Raw_Data!E123) -> 30510.15 | F123: =IF(ISBLANK(Raw_Data!F123),AVERAGE(Raw_Data!F$2:F$5002),Raw_Data!F123) -> 9916.82 | G123: =IF(ISBLANK(Raw_Data!G123),AVERAGE(Raw_Data!G$2:G$5002),Raw_Data!G123) -> 10825.76 | H123: =ROUND(D123+E123+F123,0) -> 142127.00 | I123: =+ROUND(H123-G123,0) -> 131301.00 | J123: =TEXT(Raw_Data!J123,"MMM-YYY") -> May-2025 | K123: =Raw_Data!K123 -> 1 | L123: =Raw_Data!L123 -> Kolkata-East | M123: =IF(COUNTIF($A$3:A123,A123)>1,"Duplicate","OK") -> OK | N123: =IF(AND( H123=ROUND(D123+E123+F123,0), I123=ROUND(H123-G123,0), I123>=0 ),"VALID","ERROR") -> VALID
A124: =Raw_Data!A124 -> EMP0125 | B124: Customer Support | C124: Analyst | D124: =IF(ISBLANK(Raw_Data!D124),AVERAGE(Raw_Data!D$2:D$5002),Raw_Data!D124) -> 33803.20 | E124: =IF(ISBLANK(Raw_Data!E124),AVERAGE(Raw_Data!E$2:E$5002),Raw_Data!E124) -> 10140.96 | F124: =IF(ISBLANK(Raw_Data!F124),AVERAGE(Raw_Data!F$2:F$5002),Raw_Data!F124) -> 4740.45 | G124: =IF(ISBLANK(Raw_Data!G124),AVERAGE(Raw_Data!G$2:G$5002),Raw_Data!G124) -> 2801.63 | H124: =ROUND(D124+E124+F124,0) -> 48685.00 | I124: =+ROUND(H124-G124,0) -> 45883.00 | J124: =TEXT(Raw_Data!J124,"MMM-YYY") -> Jan-2025 | K124: =Raw_Data!K124 -> 21 | L124: =Raw_Data!L124 -> Pune-West | M124: =IF(COUNTIF($A$3:A124,A124)>1,"Duplicate","OK") -> OK | N124: =IF(AND( H124=ROUND(D124+E124+F124,0), I124=ROUND(H124-G124,0), I124>=0 ),"VALID","ERROR") -> VALID
A125: =Raw_Data!A125 -> EMP0126 | B125: =TRIM(CLEAN(Raw_Data!B125)) -> Operations | C125: Executive | D125: =IF(ISBLANK(Raw_Data!D125),AVERAGE(Raw_Data!D$2:D$5002),Raw_Data!D125) -> 22753.39 | E125: =IF(ISBLANK(Raw_Data!E125),AVERAGE(Raw_Data!E$2:E$5002),Raw_Data!E125) -> 6826.02 | F125: =IF(ISBLANK(Raw_Data!F125),AVERAGE(Raw_Data!F$2:F$5002),Raw_Data!F125) -> 3276.83 | G125: =IF(ISBLANK(Raw_Data!G125),AVERAGE(Raw_Data!G$2:G$5002),Raw_Data!G125) -> 3335.04 | H125: =ROUND(D125+E125+F125,0) -> 32856.00 | I125: =+ROUND(H125-G125,0) -> 29521.00 | J125: =TEXT(Raw_Data!J125,"MMM-YYY") -> Apr-2025 | K125: =Raw_Data!K125 -> 15 | L125: =Raw_Data!L125 -> Hyderabad-South | M125: =IF(COUNTIF($A$3:A125,A125)>1,"Duplicate","OK") -> OK | N125: =IF(AND( H125=ROUND(D125+E125+F125,0), I125=ROUND(H125-G125,0), I125>=0 ),"VALID","ERROR") -> VALID
A126: =Raw_Data!A126 -> EMP0127 | B126: =TRIM(CLEAN(Raw_Data!B126)) -> Sales | C126: Team Lead | D126: =IF(ISBLANK(Raw_Data!D126),AVERAGE(Raw_Data!D$2:D$5002),Raw_Data!D126) -> 44042.64 | E126: =IF(ISBLANK(Raw_Data!E126),AVERAGE(Raw_Data!E$2:E$5002),Raw_Data!E126) -> 13212.79 | F126: =IF(ISBLANK(Raw_Data!F126),AVERAGE(Raw_Data!F$2:F$5002),Raw_Data!F126) -> 4323.41 | G126: =IF(ISBLANK(Raw_Data!G126),AVERAGE(Raw_Data!G$2:G$5002),Raw_Data!G126) -> 10476.86 | H126: =ROUND(D126+E126+F126,0) -> 61579.00 | I126: =+ROUND(H126-G126,0) -> 51102.00 | J126: =TEXT(Raw_Data!J126,"MMM-YYY") -> Feb-2025 | K126: =Raw_Data!K126 -> 21 | L126: =Raw_Data!L126 -> Chandigarh-North | M126: =IF(COUNTIF($A$3:A126,A126)>1,"Duplicate","OK") -> OK | N126: =IF(AND( H126=ROUND(D126+E126+F126,0), I126=ROUND(H126-G126,0), I126>=0 ),"VALID","ERROR") -> VALID
A127: =Raw_Data!A127 -> EMP0128 | B127: =TRIM(CLEAN(Raw_Data!B127)) -> IT | C127: Executive | D127: =IF(ISBLANK(Raw_Data!D127),AVERAGE(Raw_Data!D$2:D$5002),Raw_Data!D127) -> 25558.73 | E127: =IF(ISBLANK(Raw_Data!E127),AVERAGE(Raw_Data!E$2:E$5002),Raw_Data!E127) -> 7667.62 | F127: =IF(ISBLANK(Raw_Data!F127),AVERAGE(Raw_Data!F$2:F$5002),Raw_Data!F127) -> 1243.71 | G127: =IF(ISBLANK(Raw_Data!G127),AVERAGE(Raw_Data!G$2:G$5002),Raw_Data!G127) -> 5090.99 | H127: =ROUND(D127+E127+F127,0) -> 34470.00 | I127: =+ROUND(H127-G127,0) -> 29379.00 | J127: =TEXT(Raw_Data!J127,"MMM-YYY") -> Jun-2025 | K127: =Raw_Data!K127 -> 22 | L127: =Raw_Data!L127 -> Ahmedabad-West | M127: =IF(COUNTIF($A$3:A127,A127)>1,"Duplicate","OK") -> OK | N127: =IF(AND( H127=ROUND(D127+E127+F127,0), I127=ROUND(H127-G127,0), I127>=0 ),"VALID","ERROR") -> VALID
A128: =Raw_Data!A128 -> EMP0129 | B128: =TRIM(CLEAN(Raw_Data!B128)) -> Marketing | C128: Manager | D128: =IF(ISBLANK(Raw_Data!D128),AVERAGE(Raw_Data!D$2:D$5002),Raw_Data!D128) -> 54556.59 | E128: =IF(ISBLANK(Raw_Data!E128),AVERAGE(Raw_Data!E$2:E$5002),Raw_Data!E128) -> 16366.98 | F128: =IF(ISBLANK(Raw_Data!F128),AVERAGE(Raw_Data!F$2:F$5002),Raw_Data!F128) -> 4642.81 | G128: =IF(ISBLANK(Raw_Data!G128),AVERAGE(Raw_Data!G$2:G$5002),Raw_Data!G128) -> 12208.71 | H128: =ROUND(D128+E128+F128,0) -> 75566.00 | I128: =+ROUND(H128-G128,0) -> 63357.00 | J128: =TEXT(Raw_Data!J128,"MMM-YYY") -> Jun-2025 | K128: =Raw_Data!K128 -> 14 | L128: =Raw_Data!L128 -> Jaipur-North | M128: =IF(COUNTIF($A$3:A128,A128)>1,"Duplicate","OK") -> OK | N128: =IF(AND( H128=ROUND(D128+E128+F128,0), I128=ROUND(H128-G128,0), I128>=0 ),"VALID","ERROR") -> VALID
A129: =Raw_Data!A129 -> EMP0130 | B129: =TRIM(CLEAN(Raw_Data!B129)) -> IT | C129: Sr. Manager | D129: =IF(ISBLANK(Raw_Data!D129),AVERAGE(Raw_Data!D$2:D$5002),Raw_Data!D129) -> 76797.38 | E129: =IF(ISBLANK(Raw_Data!E129),AVERAGE(Raw_Data!E$2:E$5002),Raw_Data!E129) -> 23039.21 | F129: =IF(ISBLANK(Raw_Data!F129),AVERAGE(Raw_Data!F$2:F$5002),Raw_Data!F129) -> 4709.57 | G129: =IF(ISBLANK(Raw_Data!G129),AVERAGE(Raw_Data!G$2:G$5002),Raw_Data!G129) -> 5311.42 | H129: =ROUND(D129+E129+F129,0) -> 104546.00 | I129: =+ROUND(H129-G129,0) -> 99235.00 | J129: =TEXT(Raw_Data!J129,"MMM-YYY") -> Dec-2025 | K129: =Raw_Data!K129 -> 8 | L129: =Raw_Data!L129 -> Mumbai-HO | M129: =IF(COUNTIF($A$3:A129,A129)>1,"Duplicate","OK") -> OK | N129: =IF(AND( H129=ROUND(D129+E129+F129,0), I129=ROUND(H129-G129,0), I129>=0 ),"VALID","ERROR") -> VALID
A130: =Raw_Data!A130 -> EMP0131 | B130: =TRIM(CLEAN(Raw_Data!B130)) -> Finance | C130: Analyst | D130: =IF(ISBLANK(Raw_Data!D130),AVERAGE(Raw_Data!D$2:D$5002),Raw_Data!D130) -> 26195.55 | E130: =IF(ISBLANK(Raw_Data!E130),AVERAGE(Raw_Data!E$2:E$5002),Raw_Data!E130) -> 7858.66 | F130: =IF(ISBLANK(Raw_Data!F130),AVERAGE(Raw_Data!F$2:F$5002),Raw_Data!F130) -> 2807.45 | G130: =IF(ISBLANK(Raw_Data!G130),AVERAGE(Raw_Data!G$2:G$5002),Raw_Data!G130) -> 5989.79 | H130: =ROUND(D130+E130+F130,0) -> 36862.00 | I130: =+ROUND(H130-G130,0) -> 30872.00 | J130: =TEXT(Raw_Data!J130,"MMM-YYY") -> Mar-2025 | K130: =Raw_Data!K130 -> 12 | L130: =Raw_Data!L130 -> Delhi-North | M130: =IF(COUNTIF($A$3:A130,A130)>1,"Duplicate","OK") -> OK | N130: =IF(AND( H130=ROUND(D130+E130+F130,0), I130=ROUND(H130-G130,0), I130>=0 ),"VALID","ERROR") -> VALID
A131: =Raw_Data!A131 -> EMP0132 | B131: =TRIM(CLEAN(Raw_Data!B131)) -> Finance | C131: Executive | D131: =IF(ISBLANK(Raw_Data!D131),AVERAGE(Raw_Data!D$2:D$5002),Raw_Data!D131) -> 28499.72 | E131: =IF(ISBLANK(Raw_Data!E131),AVERAGE(Raw_Data!E$2:E$5002),Raw_Data!E131) -> 8549.92 | F131: =IF(ISBLANK(Raw_Data!F131),AVERAGE(Raw_Data!F$2:F$5002),Raw_Data!F131) -> 1576.03 | G131: =IF(ISBLANK(Raw_Data!G131),AVERAGE(Raw_Data!G$2:G$5002),Raw_Data!G131) -> 5040.92 | H131: =ROUND(D131+E131+F131,0) -> 38626.00 | I131: =+ROUND(H131-G131,0) -> 33585.00 | J131: =TEXT(Raw_Data!J131,"MMM-YYY") -> Sep-2025 | K131: =Raw_Data!K131 -> 4 | L131: =Raw_Data!L131 -> Bangalore-South | M131: =IF(COUNTIF($A$3:A131,A131)>1,"Duplicate","OK") -> OK | N131: =IF(AND( H131=ROUND(D131+E131+F131,0), I131=ROUND(H131-G131,0), I131>=0 ),"VALID","ERROR") -> VALID
A132: =Raw_Data!A132 -> EMP0133 | B132: =TRIM(CLEAN(Raw_Data!B132)) -> Operations | C132: Analyst | D132: =IF(ISBLANK(Raw_Data!D132),AVERAGE(Raw_Data!D$2:D$5002),Raw_Data!D132) -> 34805.11 | E132: =IF(ISBLANK(Raw_Data!E132),AVERAGE(Raw_Data!E$2:E$5002),Raw_Data!E132) -> 10441.53 | F132: =IF(ISBLANK(Raw_Data!F132),AVERAGE(Raw_Data!F$2:F$5002),Raw_Data!F132) -> 5795.94 | G132: =IF(ISBLANK(Raw_Data!G132),AVERAGE(Raw_Data!G$2:G$5002),Raw_Data!G132) -> 3093.27 | H132: =ROUND(D132+E132+F132,0) -> 51043.00 | I132: =+ROUND(H132-G132,0) -> 47950.00 | J132: =TEXT(Raw_Data!J132,"MMM-YYY") -> Jun-2025 | K132: =Raw_Data!K132 -> 17 | L132: =Raw_Data!L132 -> Chennai-South | M132: =IF(COUNTIF($A$3:A132,A132)>1,"Duplicate","OK") -> OK | N132: =IF(AND( H132=ROUND(D132+E132+F132,0), I132=ROUND(H132-G132,0), I132>=0 ),"VALID","ERROR") -> VALID
A133: =Raw_Data!A133 -> EMP0134 | B133: =TRIM(CLEAN(Raw_Data!B133)) -> Finance | C133: Analyst | D133: =IF(ISBLANK(Raw_Data!D133),AVERAGE(Raw_Data!D$2:D$5002),Raw_Data!D133) -> 25141.48 | E133: =IF(ISBLANK(Raw_Data!E133),AVERAGE(Raw_Data!E$2:E$5002),Raw_Data!E133) -> 7542.44 | F133: =IF(ISBLANK(Raw_Data!F133),AVERAGE(Raw_Data!F$2:F$5002),Raw_Data!F133) -> 2685.79 | G133: =IF(ISBLANK(Raw_Data!G133),AVERAGE(Raw_Data!G$2:G$5002),Raw_Data!G133) -> 2068.98 | H133: =ROUND(D133+E133+F133,0) -> 35370.00 | I133: =+ROUND(H133-G133,0) -> 33301.00 | J133: =TEXT(Raw_Data!J133,"MMM-YYY") -> Jan-2025 | K133: =Raw_Data!K133 -> 6 | L133: =Raw_Data!L133 -> Kolkata-East | M133: =IF(COUNTIF($A$3:A133,A133)>1,"Duplicate","OK") -> OK | N133: =IF(AND( H133=ROUND(D133+E133+F133,0), I133=ROUND(H133-G133,0), I133>=0 ),"VALID","ERROR") -> VALID
A134: =Raw_Data!A134 -> EMP0135 | B134: =TRIM(CLEAN(Raw_Data!B134)) -> Operations | C134: Analyst | D134: =IF(ISBLANK(Raw_Data!D134),AVERAGE(Raw_Data!D$2:D$5002),Raw_Data!D134) -> 31974.17 | E134: =IF(ISBLANK(Raw_Data!E134),AVERAGE(Raw_Data!E$2:E$5002),Raw_Data!E134) -> 9592.25 | F134: =IF(ISBLANK(Raw_Data!F134),AVERAGE(Raw_Data!F$2:F$5002),Raw_Data!F134) -> 807.54 | G134: =IF(ISBLANK(Raw_Data!G134),AVERAGE(Raw_Data!G$2:G$5002),Raw_Data!G134) -> 8330.50 | H134: =ROUND(D134+E134+F134,0) -> 42374.00 | I134: =+ROUND(H134-G134,0) -> 34044.00 | J134: =TEXT(Raw_Data!J134,"MMM-YYY") -> Aug-2025 | K134: =Raw_Data!K134 -> 9 | L134: =Raw_Data!L134 -> Pune-West | M134: =IF(COUNTIF($A$3:A134,A134)>1,"Duplicate","OK") -> OK | N134: =IF(AND( H134=ROUND(D134+E134+F134,0), I134=ROUND(H134-G134,0), I134>=0 ),"VALID","ERROR") -> VALID
A135: =Raw_Data!A135 -> EMP0136 | B135: =TRIM(CLEAN(Raw_Data!B135)) -> HR | C135: Director | D135: =IF(ISBLANK(Raw_Data!D135),AVERAGE(Raw_Data!D$2:D$5002),Raw_Data!D135) -> 90441.55 | E135: =IF(ISBLANK(Raw_Data!E135),AVERAGE(Raw_Data!E$2:E$5002),Raw_Data!E135) -> 27132.47 | F135: =IF(ISBLANK(Raw_Data!F135),AVERAGE(Raw_Data!F$2:F$5002),Raw_Data!F135) -> 5143.22 | G135: =IF(ISBLANK(Raw_Data!G135),AVERAGE(Raw_Data!G$2:G$5002),Raw_Data!G135) -> 12988.70 | H135: =ROUND(D135+E135+F135,0) -> 122717.00 | I135: =+ROUND(H135-G135,0) -> 109728.00 | J135: =TEXT(Raw_Data!J135,"MMM-YYY") -> Jun-2025 | K135: =Raw_Data!K135 -> 11 | L135: =Raw_Data!L135 -> Hyderabad-South | M135: =IF(COUNTIF($A$3:A135,A135)>1,"Duplicate","OK") -> OK | N135: =IF(AND( H135=ROUND(D135+E135+F135,0), I135=ROUND(H135-G135,0), I135>=0 ),"VALID","ERROR") -> VALID
...

Sheet Validation_Audit
A1: Validation Audit
A2: Audit built from the cleaned model logic and raw source. Raw_Data and Clean_Data were left untouched.
A4: Audit Metric | B4: Result | C4: Status | E4: ISSUELOG
A5: Raw rows | B5: 5000 | C5: RESOLVED | E5: Employee ID | F5: Issue Type | G5: Original Value | H5: Resolution
A6: Clean rows | B6: 4746 | C6: RESOLVED | E6: EMP0008 | F6: Gross Salary mismatch | G6: 46129.95 | H6: Recomputed from Basic + Allowances + Overtime
A7: Duplicate Employee IDs found | B7: 254 | C7: RESOLVED | E7: EMP0008 | F7: Net Salary mismatch | G7: 51129.95 | H7: Recomputed from Gross - Deductions
A8: Duplicate rows removed | B8: 254 | C8: RESOLVED | E8: EMP0023 | F8: Missing Deductions | H8: Filled with department average
A9: Missing Department fixed | B9: 30 | C9: RESOLVED | E9: EMP0023 | F9: Net Salary mismatch | G9: 30407.27 | H9: Recomputed from Gross - Deductions
A10: Missing Basic Pay fixed | B10: 90 | C10: RESOLVED | E10: EMP0041 | F10: Missing Deductions | H10: Filled with department average
A11: Missing Deductions fixed | B11: 90 | C11: RESOLVED | E11: EMP0041 | F11: Net Salary mismatch | G11: 110600.56 | H11: Recomputed from Gross - Deductions
A12: Gross salary mismatches corrected | B12: 3896 | C12: RESOLVED | E12: EMP0054 | F12: Missing Department | H12: Filled with mode/department logic: Marketing
A13: Net salary mismatches corrected | B13: 4028 | C13: RESOLVED | E13: EMP0055 | F13: Missing Basic Pay | H13: Filled with department average
A14: Post-clean missing cells | B14: 0 | C14: PASS | E14: EMP0055 | F14: Gross Salary mismatch | G14: 25731.7 | H14: Recomputed from Basic + Allowances + Overtime
A15: Post-clean duplicate IDs | B15: 0 | C15: PASS | E15: EMP0074 | F15: Missing Basic Pay | H15: Filled with department average
A16: Post-clean formula mismatches | B16: 0 | C16: PASS | E16: EMP0074 | F16: Gross Salary mismatch | G16: 112351.64 | H16: Recomputed from Basic + Allowances + Overtime
A17: Post-clean negative net salaries | B17: 0 | C17: PASS | E17: EMP0125 | F17: Missing Department | H17: Filled with mode/department logic: Marketing
E18: EMP0127 | F18: Gross Salary mismatch | G18: 33565.78 | H18: Recomputed from Basic + Allowances + Overtime
A19: Overall audit result | B19: =IF(SUM(B14:B16)=0,"PASS","CHECK") -> PASS | E19: EMP0127 | F19: Net Salary mismatch | G19: 38565.78 | H19: Recomputed from Gross - Deductions
E20: EMP0183 | F20: Gross Salary mismatch | G20: 78840.54 | H20: Recomputed from Basic + Allowances + Overtime
E21: EMP0183 | F21: Net Salary mismatch | G21: 83840.54 | H21: Recomputed from Gross - Deductions
E22: EMP0189 | F22: Missing Deductions | H22: Filled with department average
E23: EMP0189 | F23: Net Salary mismatch | G23: 37220.32 | H23: Recomputed from Gross - Deductions
E24: EMP0207 | F24: Missing Deductions | H24: Filled with department average
E25: EMP0207 | F25: Net Salary mismatch | G25: 93399.48 | H25: Recomputed from Gross - Deductions
E26: EMP0214 | F26: Missing Basic Pay | H26: Filled with department average
E27: EMP0214 | F27: Gross Salary mismatch | G27: 39259.94 | H27: Recomputed from Basic + Allowances + Overtime
E28: EMP0232 | F28: Missing Basic Pay | H28: Filled with department average
E29: EMP0232 | F29: Gross Salary mismatch | G29: 90055.01 | H29: Recomputed from Basic + Allowances + Overtime
E30: EMP0245 | F30: Missing Department | H30: Filled with mode/department logic: Marketing
E31: EMP0251 | F31: Missing Deductions | H31: Filled with department average
E32: EMP0251 | F32: Net Salary mismatch | G32: 36110.2 | H32: Recomputed from Gross - Deductions
E33: EMP0253 | F33: Missing Deductions | H33: Filled with department average
E34: EMP0253 | F34: Net Salary mismatch | G34: 26274.59 | H34: Recomputed from Gross - Deductions
E35: EMP0281 | F35: Missing Deductions | H35: Filled with department average
E36: EMP0281 | F36: Net Salary mismatch | G36: 45096.32 | H36: Recomputed from Gross - Deductions
E37: EMP0282 | F37: Missing Basic Pay | H37: Filled with department average
E38: EMP0282 | F38: Gross Salary mismatch | G38: 175085.23 | H38: Recomputed from Basic + Allowances + Overtime
E39: EMP0312 | F39: Gross Salary mismatch | G39: 50204.85 | H39: Recomputed from Basic + Allowances + Overtime
E40: EMP0312 | F40: Net Salary mismatch | G40: 55204.85 | H40: Recomputed from Gross - Deductions
E41: EMP0339 | F41: Missing Basic Pay | H41: Filled with department average
...

Sheet TDS
A1: TDS Analysis
A2: Indicative slab model for project analysis; linked to the cleaned payroll logic.
A4: Annual Gross From | B4: Annual Gross To | C4: Rate
A5: 0 | B5: 250000 | C5: 0
A6: 250000 | B6: 500000 | C6: 0.05
A7: 500000 | B7: 1000000 | C7: 0.2
A8: 1000000 | B8: Above | C8: 0.3
A10: Employee ID | B10: Department | C10: Designation | D10: Monthly Gross | E10: Annual Gross | F10: TDS Rate | G10: Annual TDS | H10: Monthly TDS | I10: Monthly Net After TDS
A11: EMP0001 | B11: Sales | C11: Associate | D11: 24634.11 | E11: =D11*12 -> ₹295,609.32 | F11: =IF(E11<=250000,0,IF(E11<=500000,5%,IF(E11<=1000000,20%,30%))) -> 5.0% | G11: =E11*F11 -> ₹14,780.47 | H11: =G11/12 -> ₹1,231.71 | I11: =23416.71-H11 -> ₹22,185.00
A12: EMP0002 | B12: HR | C12: Sr. Manager | D12: 118724.8 | E12: =D12*12 -> ₹1,424,697.60 | F12: =IF(E12<=250000,0,IF(E12<=500000,5%,IF(E12<=1000000,20%,30%))) -> 30.0% | G12: =E12*F12 -> ₹427,409.28 | H12: =G12/12 -> ₹35,617.44 | I12: =103798.8-H12 -> ₹68,181.36
A13: EMP0003 | B13: HR | C13: Associate | D13: 27424.83 | E13: =D13*12 -> ₹329,097.96 | F13: =IF(E13<=250000,0,IF(E13<=500000,5%,IF(E13<=1000000,20%,30%))) -> 5.0% | G13: =E13*F13 -> ₹16,454.90 | H13: =G13/12 -> ₹1,371.24 | I13: =27269-H13 -> ₹25,897.76
A14: EMP0004 | B14: Sales | C14: Sr. Manager | D14: 115188.48 | E14: =D14*12 -> ₹1,382,261.76 | F14: =IF(E14<=250000,0,IF(E14<=500000,5%,IF(E14<=1000000,20%,30%))) -> 30.0% | G14: =E14*F14 -> ₹414,678.53 | H14: =G14/12 -> ₹34,556.54 | I14: =103971.58-H14 -> ₹69,415.04
A15: EMP0005 | B15: Customer Support | C15: Director | D15: 131846.6 | E15: =D15*12 -> ₹1,582,159.20 | F15: =IF(E15<=250000,0,IF(E15<=500000,5%,IF(E15<=1000000,20%,30%))) -> 30.0% | G15: =E15*F15 -> ₹474,647.76 | H15: =G15/12 -> ₹39,553.98 | I15: =112947.84-H15 -> ₹73,393.86
A16: EMP0006 | B16: IT | C16: Executive | D16: 34711.89 | E16: =D16*12 -> ₹416,542.68 | F16: =IF(E16<=250000,0,IF(E16<=500000,5%,IF(E16<=1000000,20%,30%))) -> 5.0% | G16: =E16*F16 -> ₹20,827.13 | H16: =G16/12 -> ₹1,735.59 | I16: =33979.2-H16 -> ₹32,243.61
A17: EMP0007 | B17: HR | C17: Analyst | D17: 47559.36 | E17: =D17*12 -> ₹570,712.32 | F17: =IF(E17<=250000,0,IF(E17<=500000,5%,IF(E17<=1000000,20%,30%))) -> 20.0% | G17: =E17*F17 -> ₹114,142.46 | H17: =G17/12 -> ₹9,511.87 | I17: =39453.79-H17 -> ₹29,941.92
A18: EMP0008 | B18: Marketing | C18: Manager | D18: 70136.04 | E18: =D18*12 -> ₹841,632.48 | F18: =IF(E18<=250000,0,IF(E18<=500000,5%,IF(E18<=1000000,20%,30%))) -> 20.0% | G18: =E18*F18 -> ₹168,326.50 | H18: =G18/12 -> ₹14,027.21 | I18: =69019.12-H18 -> ₹54,991.91
A19: EMP0009 | B19: Customer Support | C19: Sr. Manager | D19: 119379.66 | E19: =D19*12 -> ₹1,432,555.92 | F19: =IF(E19<=250000,0,IF(E19<=500000,5%,IF(E19<=1000000,20%,30%))) -> 30.0% | G19: =E19*F19 -> ₹429,766.78 | H19: =G19/12 -> ₹35,813.90 | I19: =105335.88-H19 -> ₹69,521.98
A20: EMP0010 | B20: HR | C20: Associate | D20: 33108.61 | E20: =D20*12 -> ₹397,303.32 | F20: =IF(E20<=250000,0,IF(E20<=500000,5%,IF(E20<=1000000,20%,30%))) -> 5.0% | G20: =E20*F20 -> ₹19,865.17 | H20: =G20/12 -> ₹1,655.43 | I20: =26381.19-H20 -> ₹24,725.76
A21: EMP0011 | B21: Customer Support | C21: Associate | D21: 28838.45 | E21: =D21*12 -> ₹346,061.40 | F21: =IF(E21<=250000,0,IF(E21<=500000,5%,IF(E21<=1000000,20%,30%))) -> 5.0% | G21: =E21*F21 -> ₹17,303.07 | H21: =G21/12 -> ₹1,441.92 | I21: =23649.39-H21 -> ₹22,207.47
A22: EMP0012 | B22: IT | C22: Analyst | D22: 36670.35 | E22: =D22*12 -> ₹440,044.20 | F22: =IF(E22<=250000,0,IF(E22<=500000,5%,IF(E22<=1000000,20%,30%))) -> 5.0% | G22: =E22*F22 -> ₹22,002.21 | H22: =G22/12 -> ₹1,833.52 | I22: =29056.73-H22 -> ₹27,223.21
A23: EMP0013 | B23: HR | C23: Manager | D23: 79386.75 | E23: =D23*12 -> ₹952,641.00 | F23: =IF(E23<=250000,0,IF(E23<=500000,5%,IF(E23<=1000000,20%,30%))) -> 20.0% | G23: =E23*F23 -> ₹190,528.20 | H23: =G23/12 -> ₹15,877.35 | I23: =75242.37-H23 -> ₹59,365.02
A24: EMP0014 | B24: Marketing | C24: Analyst | D24: 49830.39 | E24: =D24*12 -> ₹597,964.68 | F24: =IF(E24<=250000,0,IF(E24<=500000,5%,IF(E24<=1000000,20%,30%))) -> 20.0% | G24: =E24*F24 -> ₹119,592.94 | H24: =G24/12 -> ₹9,966.08 | I24: =43999.92-H24 -> ₹34,033.84
A25: EMP0015 | B25: IT | C25: Director | D25: 154273.4 | E25: =D25*12 -> ₹1,851,280.80 | F25: =IF(E25<=250000,0,IF(E25<=500000,5%,IF(E25<=1000000,20%,30%))) -> 30.0% | G25: =E25*F25 -> ₹555,384.24 | H25: =G25/12 -> ₹46,282.02 | I25: =125265.59-H25 -> ₹78,983.57
A26: EMP0016 | B26: Marketing | C26: Analyst | D26: 38047.02 | E26: =D26*12 -> ₹456,564.24 | F26: =IF(E26<=250000,0,IF(E26<=500000,5%,IF(E26<=1000000,20%,30%))) -> 5.0% | G26: =E26*F26 -> ₹22,828.21 | H26: =G26/12 -> ₹1,902.35 | I26: =33680.55-H26 -> ₹31,778.20
A27: EMP0017 | B27: IT | C27: Executive | D27: 38295.39 | E27: =D27*12 -> ₹459,544.68 | F27: =IF(E27<=250000,0,IF(E27<=500000,5%,IF(E27<=1000000,20%,30%))) -> 5.0% | G27: =E27*F27 -> ₹22,977.23 | H27: =G27/12 -> ₹1,914.77 | I27: =30676.88-H27 -> ₹28,762.11
A28: EMP0018 | B28: Finance | C28: Analyst | D28: 38248.18 | E28: =D28*12 -> ₹458,978.16 | F28: =IF(E28<=250000,0,IF(E28<=500000,5%,IF(E28<=1000000,20%,30%))) -> 5.0% | G28: =E28*F28 -> ₹22,948.91 | H28: =G28/12 -> ₹1,912.41 | I28: =33980.08-H28 -> ₹32,067.67
A29: EMP0019 | B29: Operations | C29: Team Lead | D29: 65640.24 | E29: =D29*12 -> ₹787,682.88 | F29: =IF(E29<=250000,0,IF(E29<=500000,5%,IF(E29<=1000000,20%,30%))) -> 20.0% | G29: =E29*F29 -> ₹157,536.58 | H29: =G29/12 -> ₹13,128.05 | I29: =62510.35-H29 -> ₹49,382.30
A30: EMP0020 | B30: Operations | C30: Team Lead | D30: 47496.36 | E30: =D30*12 -> ₹569,956.32 | F30: =IF(E30<=250000,0,IF(E30<=500000,5%,IF(E30<=1000000,20%,30%))) -> 20.0% | G30: =E30*F30 -> ₹113,991.26 | H30: =G30/12 -> ₹9,499.27 | I30: =46303.18-H30 -> ₹36,803.91
A31: EMP0021 | B31: Finance | C31: Director | D31: 162503.97 | E31: =D31*12 -> ₹1,950,047.64 | F31: =IF(E31<=250000,0,IF(E31<=500000,5%,IF(E31<=1000000,20%,30%))) -> 30.0% | G31: =E31*F31 -> ₹585,014.29 | H31: =G31/12 -> ₹48,751.19 | I31: =149287.52-H31 -> ₹100,536.33
A32: EMP0022 | B32: Marketing | C32: Manager | D32: 69862.83 | E32: =D32*12 -> ₹838,353.96 | F32: =IF(E32<=250000,0,IF(E32<=500000,5%,IF(E32<=1000000,20%,30%))) -> 20.0% | G32: =E32*F32 -> ₹167,670.79 | H32: =G32/12 -> ₹13,972.57 | I32: =55860.54-H32 -> ₹41,887.97
A33: EMP0023 | B33: Sales | C33: Associate | D33: 32241.02 | E33: =D33*12 -> ₹386,892.24 | F33: =IF(E33<=250000,0,IF(E33<=500000,5%,IF(E33<=1000000,20%,30%))) -> 5.0% | G33: =E33*F33 -> ₹19,344.61 | H33: =G33/12 -> ₹1,612.05 | I33: =17913.64-H33 -> ₹16,301.59
A34: EMP0024 | B34: IT | C34: Associate | D34: 26783.37 | E34: =D34*12 -> ₹321,400.44 | F34: =IF(E34<=250000,0,IF(E34<=500000,5%,IF(E34<=1000000,20%,30%))) -> 5.0% | G34: =E34*F34 -> ₹16,070.02 | H34: =G34/12 -> ₹1,339.17 | I34: =26763.79-H34 -> ₹25,424.62
A35: EMP0025 | B35: Sales | C35: Analyst | D35: 50425.43 | E35: =D35*12 -> ₹605,105.16 | F35: =IF(E35<=250000,0,IF(E35<=500000,5%,IF(E35<=1000000,20%,30%))) -> 20.0% | G35: =E35*F35 -> ₹121,021.03 | H35: =G35/12 -> ₹10,085.09 | I35: =45137.59-H35 -> ₹35,052.50
A36: EMP0026 | B36: Customer Support | C36: Sr. Manager | D36: 103885.37 | E36: =D36*12 -> ₹1,246,624.44 | F36: =IF(E36<=250000,0,IF(E36<=500000,5%,IF(E36<=1000000,20%,30%))) -> 30.0% | G36: =E36*F36 -> ₹373,987.33 | H36: =G36/12 -> ₹31,165.61 | I36: =90592.85-H36 -> ₹59,427.24
A37: EMP0027 | B37: IT | C37: Director | D37: 142832.56 | E37: =D37*12 -> ₹1,713,990.72 | F37: =IF(E37<=250000,0,IF(E37<=500000,5%,IF(E37<=1000000,20%,30%))) -> 30.0% | G37: =E37*F37 -> ₹514,197.22 | H37: =G37/12 -> ₹42,849.77 | I37: =116317.44-H37 -> ₹73,467.67
A38: EMP0028 | B38: Operations | C38: Analyst | D38: 39520.54 | E38: =D38*12 -> ₹474,246.48 | F38: =IF(E38<=250000,0,IF(E38<=500000,5%,IF(E38<=1000000,20%,30%))) -> 5.0% | G38: =E38*F38 -> ₹23,712.32 | H38: =G38/12 -> ₹1,976.03 | I38: =36266.12-H38 -> ₹34,290.09
A39: EMP0029 | B39: Finance | C39: Associate | D39: 27893.84 | E39: =D39*12 -> ₹334,726.08 | F39: =IF(E39<=250000,0,IF(E39<=500000,5%,IF(E39<=1000000,20%,30%))) -> 5.0% | G39: =E39*F39 -> ₹16,736.30 | H39: =G39/12 -> ₹1,394.69 | I39: =27427.58-H39 -> ₹26,032.89
A40: EMP0030 | B40: Marketing | C40: Director | D40: 134309.01 | E40: =D40*12 -> ₹1,611,708.12 | F40: =IF(E40<=250000,0,IF(E40<=500000,5%,IF(E40<=1000000,20%,30%))) -> 30.0% | G40: =E40*F40 -> ₹483,512.44 | H40: =G40/12 -> ₹40,292.70 | I40: =113059.02-H40 -> ₹72,766.32
A41: EMP0031 | B41: Sales | C41: Team Lead | D41: 64326.31 | E41: =D41*12 -> ₹771,915.72 | F41: =IF(E41<=250000,0,IF(E41<=500000,5%,IF(E41<=1000000,20%,30%))) -> 20.0% | G41: =E41*F41 -> ₹154,383.14 | H41: =G41/12 -> ₹12,865.26 | I41: =56687.3-H41 -> ₹43,822.04
A42: EMP0032 | B42: Marketing | C42: Executive | D42: 43784.71 | E42: =D42*12 -> ₹525,416.52 | F42: =IF(E42<=250000,0,IF(E42<=500000,5%,IF(E42<=1000000,20%,30%))) -> 20.0% | G42: =E42*F42 -> ₹105,083.30 | H42: =G42/12 -> ₹8,756.94 | I42: =37539.8-H42 -> ₹28,782.86
...

Sheet Department_Analysis
A1: Department Analysis
A2: Summary built from the cleaned payroll model.
A4: Department | B4: Employees | C4: Avg Basic | D4: Avg Allowances | E4: Avg Deductions | F4: Avg Gross | G4: Avg Net | H4: Total Payroll
A5: HR | B5: 653 | C5: 72382.029 | D5: 24448.517 | E5: 14750.194 | F5: 116727.81 | G5: 101977.62 | H5: 66591386
A6: Finance | B6: 697 | C6: 71687.879 | D6: 24794.31 | E6: 14499.97 | F6: 116334.54 | G6: 101834.57 | H6: 70978696
A7: IT | B7: 641 | C7: 72235.396 | D7: 24622.536 | E7: 14813.525 | F7: 116590.6 | G7: 101777.07 | H7: 65239102
A8: Operations | B8: 694 | C8: 72064.628 | D8: 24186.992 | E8: 14727.327 | F8: 116289.94 | G8: 101562.61 | H8: 70484451
A9: Customer Support | B9: 619 | C9: 71905.381 | D9: 24401.45 | E9: 14590.705 | F9: 116097.89 | G9: 101507.18 | H9: 62832946
A10: Sales | B10: 695 | C10: 71815.976 | D10: 24274.673 | E10: 14369.838 | F10: 115486.4 | G10: 101116.56 | H10: 70276008
A11: Marketing | B11: 745 | C11: 71053.548 | D11: 23736.285 | E11: 14274.261 | F11: 113708.12 | G11: 99433.858 | H11: 74078224

Sheet Designation_Analysis
A1: Designation Analysis
A2: Summary built from the cleaned payroll model.
A4: Designation | B4: Employees | C4: Avg Basic | D4: Avg Allowances | E4: Avg Deductions | F4: Avg Gross | G4: Avg Net | H4: Total Payroll
A5: Director | B5: 755 | C5: 83908.05 | D5: 27876.652 | E5: 16225.979 | F5: 132381.4 | G5: 116155.42 | H5: 87697340
A6: Sr. Manager | B6: 656 | C6: 76150.565 | D6: 25753.006 | E6: 15411.189 | F6: 121892.47 | G6: 106481.28 | H6: 69851718
A7: Manager | B7: 672 | C7: 72677.061 | D7: 24352.125 | E7: 14539.658 | F7: 116775.26 | G7: 102235.6 | H7: 68702325
A8: Team Lead | B8: 645 | C8: 69564.474 | D8: 23805.34 | E8: 14344.025 | F8: 112862.72 | G8: 98518.691 | H8: 63544556
A9: Analyst | B9: 675 | C9: 66947.247 | D9: 22978.313 | E9: 13916.527 | F9: 108910.74 | G9: 94994.21 | H9: 64121092
A10: Associate | B10: 706 | C10: 66676.444 | D10: 22560.622 | E10: 13662.104 | F10: 108430.38 | G10: 94768.28 | H10: 66906405
A11: Executive | B11: 635 | C11: 65555.44 | D11: 22639.661 | E11: 13678.108 | F11: 107626.73 | G11: 93948.623 | H11: 59657375

Sheet Monthly_Analysis_Final
A1: Monthly Analysis
A2: Monthly trend summary built from the cleaned payroll model.
A4: Pay Month | B4: Employees | C4: Total Gross | D4: Total Net | E4: Avg Net | F4: Avg Deductions
A5: 45658 | B5: 362 | C5: 41467577 | D5: 36316254 | E5: 100321.14 | F5: 14230.174
A6: 45689 | B6: 356 | C6: 41628106 | D6: 36443659 | E6: 102369.83 | F6: 14563.052
A7: 45717 | B7: 351 | C7: 40382553 | D7: 35235383 | E7: 100385.71 | F7: 14664.302
A8: 45748 | B8: 384 | C8: 44692275 | D8: 39000140 | E8: 101562.86 | F8: 14823.27
A9: 45778 | B9: 476 | C9: 54261701 | D9: 47318553 | E9: 99408.724 | F9: 14586.446
A10: 45809 | B10: 418 | C10: 48758640 | D10: 42660956 | E10: 102059.7 | F10: 14587.762
A11: 45839 | B11: 364 | C11: 42523040 | D11: 37107119 | E11: 101942.64 | F11: 14878.904
A12: 45870 | B12: 394 | C12: 45479710 | D12: 39987711 | E12: 101491.65 | F12: 13939.084
A13: 45901 | B13: 389 | C13: 44284877 | D13: 38589940 | E13: 99202.931 | F13: 14639.94
A14: 45931 | B14: 381 | C14: 44632023 | D14: 39010105 | E14: 102388.73 | F14: 14755.69
A15: 45962 | B15: 463 | C15: 54726487 | D15: 47987461 | E15: 103644.62 | F15: 14555.131
A16: 45992 | B16: 406 | C16: 46751424 | D16: 40823532 | E16: 100550.57 | F16: 14600.718

Sheet Dashboard_Helper
A1: Department | B1: Designation | C1: Pay Month | D1: Employee ID | E1: Basic Pay | F1: Allowances | G1: Overtime Amount | H1: Deductions | I1: Gross Salary | J1: Net Salary | L1: Departments | M1: Designations | N1: Months
A2: Sales | B2: Associate | C2: Dec-25 | D2: EMP0001 | E2: 18180.08 | F2: 5454.02 | G2: 1000.01 | H2: 1217.4 | I2: 24634.11 | J2: 23416.71 | L2: All | M2: All | N2: All
A3: HR | B3: Sr. Manager | C3: Jan-25 | D3: EMP0002 | E3: 84257.36 | F3: 25277.21 | G3: 9190.23 | H3: 14926 | I3: 118724.8 | J3: 103798.8 | L3: Customer Support | M3: Analyst | N3: Jan-25
A4: HR | B4: Associate | C4: Apr-25 | D4: EMP0003 | E4: 19574.19 | F4: 5872.26 | G4: 1978.38 | H4: 155.83 | I4: 27424.83 | J4: 27269 | L4: Finance | M4: Associate | N4: Feb-25
A5: Sales | B5: Sr. Manager | C5: May-25 | D5: EMP0004 | E5: 83234.45 | F5: 24970.33 | G5: 6983.7 | H5: 11216.9 | I5: 115188.48 | J5: 103971.58 | L5: HR | M5: Director | N5: Mar-25
A6: Customer Support | B6: Director | C6: Jun-25 | D6: EMP0005 | E6: 90233.96 | F6: 27070.19 | G6: 14542.45 | H6: 18898.76 | I6: 131846.6 | J6: 112947.84 | L6: IT | M6: Executive | N6: Apr-25
A7: IT | B7: Executive | C7: Jul-25 | D7: EMP0006 | E7: 23894.76 | F7: 7168.43 | G7: 3648.7 | H7: 732.69 | I7: 34711.89 | J7: 33979.2 | L7: Marketing | M7: Manager | N7: May-25
A8: HR | B8: Analyst | C8: Dec-25 | D8: EMP0007 | E8: 33474.94 | F8: 10042.48 | G8: 4041.94 | H8: 8105.57 | I8: 47559.36 | J8: 39453.79 | L8: Operations | M8: Sr. Manager | N8: Jun-25
A9: Marketing | B9: Manager | C9: May-25 | D9: EMP0008 | E9: 47246.87 | F9: 14174.06 | G9: 8715.11 | H9: 1116.92 | I9: 70136.04 | J9: 69019.12 | L9: Sales | M9: Team Lead | N9: Jul-25
A10: Customer Support | B10: Sr. Manager | C10: Dec-25 | D10: EMP0009 | E10: 81081.51 | F10: 24324.45 | G10: 13973.7 | H10: 14043.78 | I10: 119379.66 | J10: 105335.88 | N10: Aug-25
A11: HR | B11: Associate | C11: Apr-25 | D11: EMP0010 | E11: 22761.1 | F11: 6828.33 | G11: 3519.18 | H11: 6727.42 | I11: 33108.61 | J11: 26381.19 | N11: Sep-25
A12: Customer Support | B12: Associate | C12: Mar-25 | D12: EMP0011 | E12: 20736.91 | F12: 6221.07 | G12: 1880.47 | H12: 5189.06 | I12: 28838.45 | J12: 23649.39 | N12: Oct-25
A13: IT | B13: Analyst | C13: Nov-25 | D13: EMP0012 | E13: 27095.07 | F13: 8128.52 | G13: 1446.76 | H13: 7613.62 | I13: 36670.35 | J13: 29056.73 | N13: Nov-25
A14: HR | B14: Manager | C14: Aug-25 | D14: EMP0013 | E14: 56429.61 | F14: 16928.88 | G14: 6028.26 | H14: 4144.38 | I14: 79386.75 | J14: 75242.37 | N14: Dec-25
A15: Marketing | B15: Analyst | C15: Nov-25 | D15: EMP0014 | E15: 34895.23 | F15: 10468.57 | G15: 4466.59 | H15: 5830.47 | I15: 49830.39 | J15: 43999.92
A16: IT | B16: Director | C16: Jun-25 | D16: EMP0015 | E16: 117659.29 | F16: 35297.79 | G16: 1316.32 | H16: 29007.81 | I16: 154273.4 | J16: 125265.59
A17: Marketing | B17: Analyst | C17: Dec-25 | D17: EMP0016 | E17: 25661.89 | F17: 7698.57 | G17: 4686.56 | H17: 4366.47 | I17: 38047.02 | J17: 33680.55
A18: IT | B18: Executive | C18: Aug-25 | D18: EMP0017 | E18: 27767.86 | F18: 8330.36 | G18: 2197.17 | H18: 7618.51 | I18: 38295.39 | J18: 30676.88
A19: Finance | B19: Analyst | C19: Dec-25 | D19: EMP0018 | E19: 26396.3 | F19: 7918.89 | G19: 3932.99 | H19: 4268.1 | I19: 38248.18 | J19: 33980.08
A20: Operations | B20: Team Lead | C20: Mar-25 | D20: EMP0019 | E20: 47569.52 | F20: 14270.86 | G20: 3799.86 | H20: 3129.89 | I20: 65640.24 | J20: 62510.35
A21: Operations | B21: Team Lead | C21: Nov-25 | D21: EMP0020 | E21: 36272.73 | F21: 10881.82 | G21: 341.81 | H21: 1193.18 | I21: 47496.36 | J21: 46303.18
A22: Finance | B22: Director | C22: Oct-25 | D22: EMP0021 | E22: 114497.32 | F22: 34349.2 | G22: 13657.45 | H22: 13216.45 | I22: 162503.97 | J22: 149287.52
A23: Marketing | B23: Manager | C23: Nov-25 | D23: EMP0022 | E23: 49525.45 | F23: 14857.63 | G23: 5479.75 | H23: 14002.29 | I23: 69862.83 | J23: 55860.54
A24: Sales | B24: Associate | C24: Nov-25 | D24: EMP0023 | E24: 22908.31 | F24: 6872.49 | G24: 2460.22 | H24: 14327.383 | I24: 32241.02 | J24: 17913.64
A25: IT | B25: Associate | C25: Jan-25 | D25: EMP0024 | E25: 20113.2 | F25: 6033.96 | G25: 636.21 | H25: 19.58 | I25: 26783.37 | J25: 26763.79
A26: Sales | B26: Analyst | C26: Feb-25 | D26: EMP0025 | E26: 34718.88 | F26: 10415.66 | G26: 5290.89 | H26: 5287.84 | I26: 50425.43 | J26: 45137.59
